[2019-09-26 11:24:02,277][Thread-4:18856][task_id:django.request][log.py:228][ERROR][Internal Server Error: /goods/]
Traceback (most recent call last):
  File "D:\python_env\django_env\lib\site-packages\django\core\handlers\exception.py", line 34, in inner
    response = get_response(request)
  File "D:\python_env\django_env\lib\site-packages\django\core\handlers\base.py", line 115, in _get_response
    response = self.process_exception_by_middleware(e, request)
  File "D:\python_env\django_env\lib\site-packages\django\core\handlers\base.py", line 113, in _get_response
    response = wrapped_callback(request, *callback_args, **callback_kwargs)
  File "D:\python_env\django_env\lib\site-packages\django\views\generic\base.py", line 71, in view
    return self.dispatch(request, *args, **kwargs)
  File "D:\python_env\django_env\lib\site-packages\django\views\generic\base.py", line 97, in dispatch
    return handler(request, *args, **kwargs)
  File "D:\vue_django\backend\apps\goods\views_base.py", line 30, in get
    return HttpResponse(json.dumps(json_list),content_type="application/json")
  File "c:\python36\Lib\json\__init__.py", line 231, in dumps
    return _default_encoder.encode(obj)
  File "c:\python36\Lib\json\encoder.py", line 199, in encode
    chunks = self.iterencode(o, _one_shot=True)
  File "c:\python36\Lib\json\encoder.py", line 257, in iterencode
    return _iterencode(o, 0)
  File "c:\python36\Lib\json\encoder.py", line 180, in default
    o.__class__.__name__)
TypeError: Object of type 'datetime' is not JSON serializable
[2019-09-26 11:27:06,884][Thread-1:15052][task_id:django.request][log.py:228][ERROR][Internal Server Error: /goods/]
Traceback (most recent call last):
  File "D:\python_env\django_env\lib\site-packages\django\core\handlers\exception.py", line 34, in inner
    response = get_response(request)
  File "D:\python_env\django_env\lib\site-packages\django\core\handlers\base.py", line 115, in _get_response
    response = self.process_exception_by_middleware(e, request)
  File "D:\python_env\django_env\lib\site-packages\django\core\handlers\base.py", line 113, in _get_response
    response = wrapped_callback(request, *callback_args, **callback_kwargs)
  File "D:\python_env\django_env\lib\site-packages\django\views\generic\base.py", line 71, in view
    return self.dispatch(request, *args, **kwargs)
  File "D:\python_env\django_env\lib\site-packages\django\views\generic\base.py", line 97, in dispatch
    return handler(request, *args, **kwargs)
  File "D:\vue_django\backend\apps\goods\views_base.py", line 34, in get
    logger.debug("debug logs is :" + json_list)
TypeError: must be str, not list
[2019-09-26 14:38:43,558][Thread-6:2360][task_id:django.request][log.py:228][ERROR][Internal Server Error: /goods/]
Traceback (most recent call last):
  File "D:\python_env\django_env\lib\site-packages\django\core\handlers\exception.py", line 34, in inner
    response = get_response(request)
  File "D:\python_env\django_env\lib\site-packages\django\core\handlers\base.py", line 115, in _get_response
    response = self.process_exception_by_middleware(e, request)
  File "D:\python_env\django_env\lib\site-packages\django\core\handlers\base.py", line 113, in _get_response
    response = wrapped_callback(request, *callback_args, **callback_kwargs)
  File "D:\python_env\django_env\lib\site-packages\django\views\generic\base.py", line 71, in view
    return self.dispatch(request, *args, **kwargs)
  File "D:\python_env\django_env\lib\site-packages\django\views\generic\base.py", line 97, in dispatch
    return handler(request, *args, **kwargs)
  File "D:\vue_django\backend\apps\goods\views_base.py", line 57, in get
    return HttpResponse(json.dumps(json_list),content_type="application/json")
  File "c:\python36\Lib\json\__init__.py", line 231, in dumps
    return _default_encoder.encode(obj)
  File "c:\python36\Lib\json\encoder.py", line 199, in encode
    chunks = self.iterencode(o, _one_shot=True)
  File "c:\python36\Lib\json\encoder.py", line 257, in iterencode
    return _iterencode(o, 0)
  File "c:\python36\Lib\json\encoder.py", line 180, in default
    o.__class__.__name__)
TypeError: Object of type 'ImageFieldFile' is not JSON serializable
[2019-09-26 14:46:48,333][Thread-1:25196][task_id:django.request][log.py:228][ERROR][Internal Server Error: /goods/]
Traceback (most recent call last):
  File "D:\python_env\django_env\lib\site-packages\django\core\handlers\exception.py", line 34, in inner
    response = get_response(request)
  File "D:\python_env\django_env\lib\site-packages\django\core\handlers\base.py", line 115, in _get_response
    response = self.process_exception_by_middleware(e, request)
  File "D:\python_env\django_env\lib\site-packages\django\core\handlers\base.py", line 113, in _get_response
    response = wrapped_callback(request, *callback_args, **callback_kwargs)
  File "D:\python_env\django_env\lib\site-packages\django\views\generic\base.py", line 71, in view
    return self.dispatch(request, *args, **kwargs)
  File "D:\python_env\django_env\lib\site-packages\django\views\generic\base.py", line 97, in dispatch
    return handler(request, *args, **kwargs)
  File "D:\vue_django\backend\apps\goods\views_base.py", line 62, in get
    return JsonResponse(json_data)
  File "D:\python_env\django_env\lib\site-packages\django\http\response.py", line 552, in __init__
    'In order to allow non-dict objects to be serialized set the '
TypeError: In order to allow non-dict objects to be serialized set the safe parameter to False.
[2019-09-26 14:58:04,194][Thread-1:15420][task_id:django.request][log.py:228][ERROR][Internal Server Error: /goods/]
Traceback (most recent call last):
  File "D:\python_env\django_env\lib\site-packages\django\core\handlers\exception.py", line 34, in inner
    response = get_response(request)
  File "D:\python_env\django_env\lib\site-packages\django\core\handlers\base.py", line 115, in _get_response
    response = self.process_exception_by_middleware(e, request)
  File "D:\python_env\django_env\lib\site-packages\django\core\handlers\base.py", line 113, in _get_response
    response = wrapped_callback(request, *callback_args, **callback_kwargs)
  File "D:\python_env\django_env\lib\site-packages\django\views\generic\base.py", line 71, in view
    return self.dispatch(request, *args, **kwargs)
  File "D:\python_env\django_env\lib\site-packages\django\views\generic\base.py", line 97, in dispatch
    return handler(request, *args, **kwargs)
  File "D:\vue_django\backend\apps\goods\views_base.py", line 62, in get
    return JsonResponse(json_data,safe=True)
  File "D:\python_env\django_env\lib\site-packages\django\http\response.py", line 552, in __init__
    'In order to allow non-dict objects to be serialized set the '
TypeError: In order to allow non-dict objects to be serialized set the safe parameter to False.
[2019-09-26 14:59:32,691][Thread-1:24864][task_id:django.request][log.py:228][ERROR][Internal Server Error: /goods/]
Traceback (most recent call last):
  File "D:\python_env\django_env\lib\site-packages\django\core\handlers\exception.py", line 34, in inner
    response = get_response(request)
  File "D:\python_env\django_env\lib\site-packages\django\core\handlers\base.py", line 115, in _get_response
    response = self.process_exception_by_middleware(e, request)
  File "D:\python_env\django_env\lib\site-packages\django\core\handlers\base.py", line 113, in _get_response
    response = wrapped_callback(request, *callback_args, **callback_kwargs)
  File "D:\python_env\django_env\lib\site-packages\django\views\generic\base.py", line 71, in view
    return self.dispatch(request, *args, **kwargs)
  File "D:\python_env\django_env\lib\site-packages\django\views\generic\base.py", line 97, in dispatch
    return handler(request, *args, **kwargs)
  File "D:\vue_django\backend\apps\goods\views_base.py", line 60, in get
    json_data = json.loads(json_data)
  File "c:\python36\Lib\json\__init__.py", line 354, in loads
    return _default_decoder.decode(s)
  File "c:\python36\Lib\json\decoder.py", line 339, in decode
    obj, end = self.raw_decode(s, idx=_w(s, 0).end())
  File "c:\python36\Lib\json\decoder.py", line 357, in raw_decode
    raise JSONDecodeError("Expecting value", s, err.value) from None
json.decoder.JSONDecodeError: Expecting value: line 1 column 2 (char 1)
[2019-09-26 15:01:01,383][Thread-1:20404][task_id:django.request][log.py:228][ERROR][Internal Server Error: /goods/]
Traceback (most recent call last):
  File "D:\python_env\django_env\lib\site-packages\django\core\handlers\exception.py", line 34, in inner
    response = get_response(request)
  File "D:\python_env\django_env\lib\site-packages\django\core\handlers\base.py", line 115, in _get_response
    response = self.process_exception_by_middleware(e, request)
  File "D:\python_env\django_env\lib\site-packages\django\core\handlers\base.py", line 113, in _get_response
    response = wrapped_callback(request, *callback_args, **callback_kwargs)
  File "D:\python_env\django_env\lib\site-packages\django\views\generic\base.py", line 71, in view
    return self.dispatch(request, *args, **kwargs)
  File "D:\python_env\django_env\lib\site-packages\django\views\generic\base.py", line 97, in dispatch
    return handler(request, *args, **kwargs)
  File "D:\vue_django\backend\apps\goods\views_base.py", line 60, in get
    json_data = json.loads(json_data)
  File "c:\python36\Lib\json\__init__.py", line 354, in loads
    return _default_decoder.decode(s)
  File "c:\python36\Lib\json\decoder.py", line 339, in decode
    obj, end = self.raw_decode(s, idx=_w(s, 0).end())
  File "c:\python36\Lib\json\decoder.py", line 357, in raw_decode
    raise JSONDecodeError("Expecting value", s, err.value) from None
json.decoder.JSONDecodeError: Expecting value: line 1 column 2 (char 1)
[2019-09-26 15:02:01,871][Thread-1:26116][task_id:django.request][log.py:228][ERROR][Internal Server Error: /goods/]
Traceback (most recent call last):
  File "D:\python_env\django_env\lib\site-packages\django\core\handlers\exception.py", line 34, in inner
    response = get_response(request)
  File "D:\python_env\django_env\lib\site-packages\django\core\handlers\base.py", line 115, in _get_response
    response = self.process_exception_by_middleware(e, request)
  File "D:\python_env\django_env\lib\site-packages\django\core\handlers\base.py", line 113, in _get_response
    response = wrapped_callback(request, *callback_args, **callback_kwargs)
  File "D:\python_env\django_env\lib\site-packages\django\views\generic\base.py", line 71, in view
    return self.dispatch(request, *args, **kwargs)
  File "D:\python_env\django_env\lib\site-packages\django\views\generic\base.py", line 97, in dispatch
    return handler(request, *args, **kwargs)
  File "D:\vue_django\backend\apps\goods\views_base.py", line 61, in get
    json_data = json.loads(json_data)
  File "c:\python36\Lib\json\__init__.py", line 354, in loads
    return _default_decoder.decode(s)
  File "c:\python36\Lib\json\decoder.py", line 339, in decode
    obj, end = self.raw_decode(s, idx=_w(s, 0).end())
  File "c:\python36\Lib\json\decoder.py", line 357, in raw_decode
    raise JSONDecodeError("Expecting value", s, err.value) from None
json.decoder.JSONDecodeError: Expecting value: line 1 column 2 (char 1)
[2019-09-26 15:03:14,048][Thread-1:13132][task_id:django.request][log.py:228][ERROR][Internal Server Error: /goods/]
Traceback (most recent call last):
  File "D:\python_env\django_env\lib\site-packages\django\core\handlers\exception.py", line 34, in inner
    response = get_response(request)
  File "D:\python_env\django_env\lib\site-packages\django\core\handlers\base.py", line 115, in _get_response
    response = self.process_exception_by_middleware(e, request)
  File "D:\python_env\django_env\lib\site-packages\django\core\handlers\base.py", line 113, in _get_response
    response = wrapped_callback(request, *callback_args, **callback_kwargs)
  File "D:\python_env\django_env\lib\site-packages\django\views\generic\base.py", line 71, in view
    return self.dispatch(request, *args, **kwargs)
  File "D:\python_env\django_env\lib\site-packages\django\views\generic\base.py", line 97, in dispatch
    return handler(request, *args, **kwargs)
  File "D:\vue_django\backend\apps\goods\views_base.py", line 61, in get
    json_data = json.loads(json_data)
  File "c:\python36\Lib\json\__init__.py", line 354, in loads
    return _default_decoder.decode(s)
  File "c:\python36\Lib\json\decoder.py", line 339, in decode
    obj, end = self.raw_decode(s, idx=_w(s, 0).end())
  File "c:\python36\Lib\json\decoder.py", line 357, in raw_decode
    raise JSONDecodeError("Expecting value", s, err.value) from None
json.decoder.JSONDecodeError: Expecting value: line 1 column 2 (char 1)
[2019-09-26 15:04:49,720][Thread-1:19000][task_id:django.request][log.py:228][ERROR][Internal Server Error: /goods/]
Traceback (most recent call last):
  File "D:\python_env\django_env\lib\site-packages\django\core\handlers\exception.py", line 34, in inner
    response = get_response(request)
  File "D:\python_env\django_env\lib\site-packages\django\core\handlers\base.py", line 115, in _get_response
    response = self.process_exception_by_middleware(e, request)
  File "D:\python_env\django_env\lib\site-packages\django\core\handlers\base.py", line 113, in _get_response
    response = wrapped_callback(request, *callback_args, **callback_kwargs)
  File "D:\python_env\django_env\lib\site-packages\django\views\generic\base.py", line 71, in view
    return self.dispatch(request, *args, **kwargs)
  File "D:\python_env\django_env\lib\site-packages\django\views\generic\base.py", line 97, in dispatch
    return handler(request, *args, **kwargs)
  File "D:\vue_django\backend\apps\goods\views_base.py", line 62, in get
    return JsonResponse(json_data,safe=True)
  File "D:\python_env\django_env\lib\site-packages\django\http\response.py", line 552, in __init__
    'In order to allow non-dict objects to be serialized set the '
TypeError: In order to allow non-dict objects to be serialized set the safe parameter to False.
[2019-09-27 15:39:17,290][Thread-1:24584][task_id:django.request][log.py:228][ERROR][Internal Server Error: /goods/]
Traceback (most recent call last):
  File "D:\python_env\django_env\lib\site-packages\django\core\handlers\exception.py", line 34, in inner
    response = get_response(request)
  File "D:\python_env\django_env\lib\site-packages\django\core\handlers\base.py", line 115, in _get_response
    response = self.process_exception_by_middleware(e, request)
  File "D:\python_env\django_env\lib\site-packages\django\core\handlers\base.py", line 113, in _get_response
    response = wrapped_callback(request, *callback_args, **callback_kwargs)
  File "D:\python_env\django_env\lib\site-packages\django\views\decorators\csrf.py", line 54, in wrapped_view
    return view_func(*args, **kwargs)
  File "D:\python_env\django_env\lib\site-packages\rest_framework\viewsets.py", line 114, in view
    return self.dispatch(request, *args, **kwargs)
  File "D:\python_env\django_env\lib\site-packages\rest_framework\views.py", line 505, in dispatch
    response = self.handle_exception(exc)
  File "D:\python_env\django_env\lib\site-packages\rest_framework\views.py", line 465, in handle_exception
    self.raise_uncaught_exception(exc)
  File "D:\python_env\django_env\lib\site-packages\rest_framework\views.py", line 476, in raise_uncaught_exception
    raise exc
  File "D:\python_env\django_env\lib\site-packages\rest_framework\views.py", line 502, in dispatch
    response = handler(request, *args, **kwargs)
  File "D:\python_env\django_env\lib\site-packages\rest_framework\mixins.py", line 38, in list
    queryset = self.filter_queryset(self.get_queryset())
  File "D:\python_env\django_env\lib\site-packages\rest_framework\generics.py", line 149, in filter_queryset
    for backend in list(self.filter_backends):
TypeError: 'RenameAttributes' object is not iterable
[2019-09-27 15:39:55,885][Thread-1:19668][task_id:django.request][log.py:228][ERROR][Internal Server Error: /goods/]
Traceback (most recent call last):
  File "D:\python_env\django_env\lib\site-packages\django\core\handlers\exception.py", line 34, in inner
    response = get_response(request)
  File "D:\python_env\django_env\lib\site-packages\django\core\handlers\base.py", line 145, in _get_response
    response = self.process_exception_by_middleware(e, request)
  File "D:\python_env\django_env\lib\site-packages\django\core\handlers\base.py", line 143, in _get_response
    response = response.render()
  File "D:\python_env\django_env\lib\site-packages\django\template\response.py", line 106, in render
    self.content = self.rendered_content
  File "D:\python_env\django_env\lib\site-packages\rest_framework\response.py", line 70, in rendered_content
    ret = renderer.render(self.data, accepted_media_type, context)
  File "D:\python_env\django_env\lib\site-packages\rest_framework\renderers.py", line 725, in render
    context = self.get_context(data, accepted_media_type, renderer_context)
  File "D:\python_env\django_env\lib\site-packages\rest_framework\renderers.py", line 703, in get_context
    'filter_form': self.get_filter_form(data, view, request),
  File "D:\python_env\django_env\lib\site-packages\rest_framework\renderers.py", line 635, in get_filter_form
    html = backend().to_html(request, queryset, view)
  File "D:\python_env\django_env\lib\site-packages\django_filters\rest_framework\backends.py", line 103, in to_html
    template = loader.get_template(self.template)
  File "D:\python_env\django_env\lib\site-packages\django\template\loader.py", line 19, in get_template
    raise TemplateDoesNotExist(template_name, chain=chain)
django.template.exceptions.TemplateDoesNotExist: django_filters/rest_framework/crispy_form.html
[2019-09-27 15:40:11,582][Thread-1:25752][task_id:django.request][log.py:228][ERROR][Internal Server Error: /goods/]
Traceback (most recent call last):
  File "D:\python_env\django_env\lib\site-packages\django\core\handlers\exception.py", line 34, in inner
    response = get_response(request)
  File "D:\python_env\django_env\lib\site-packages\django\core\handlers\base.py", line 145, in _get_response
    response = self.process_exception_by_middleware(e, request)
  File "D:\python_env\django_env\lib\site-packages\django\core\handlers\base.py", line 143, in _get_response
    response = response.render()
  File "D:\python_env\django_env\lib\site-packages\django\template\response.py", line 106, in render
    self.content = self.rendered_content
  File "D:\python_env\django_env\lib\site-packages\rest_framework\response.py", line 70, in rendered_content
    ret = renderer.render(self.data, accepted_media_type, context)
  File "D:\python_env\django_env\lib\site-packages\rest_framework\renderers.py", line 725, in render
    context = self.get_context(data, accepted_media_type, renderer_context)
  File "D:\python_env\django_env\lib\site-packages\rest_framework\renderers.py", line 703, in get_context
    'filter_form': self.get_filter_form(data, view, request),
  File "D:\python_env\django_env\lib\site-packages\rest_framework\renderers.py", line 635, in get_filter_form
    html = backend().to_html(request, queryset, view)
  File "D:\python_env\django_env\lib\site-packages\django_filters\rest_framework\backends.py", line 103, in to_html
    template = loader.get_template(self.template)
  File "D:\python_env\django_env\lib\site-packages\django\template\loader.py", line 19, in get_template
    raise TemplateDoesNotExist(template_name, chain=chain)
django.template.exceptions.TemplateDoesNotExist: django_filters/rest_framework/crispy_form.html
[2019-09-29 16:10:33,049][Thread-5:24628][task_id:django.request][log.py:228][ERROR][Internal Server Error: /goods/]
Traceback (most recent call last):
  File "D:\python_env\django_env\lib\site-packages\django\core\handlers\exception.py", line 34, in inner
    response = get_response(request)
  File "D:\python_env\django_env\lib\site-packages\django\core\handlers\base.py", line 115, in _get_response
    response = self.process_exception_by_middleware(e, request)
  File "D:\python_env\django_env\lib\site-packages\django\core\handlers\base.py", line 113, in _get_response
    response = wrapped_callback(request, *callback_args, **callback_kwargs)
  File "D:\python_env\django_env\lib\site-packages\django\views\decorators\csrf.py", line 54, in wrapped_view
    return view_func(*args, **kwargs)
  File "D:\python_env\django_env\lib\site-packages\rest_framework\viewsets.py", line 114, in view
    return self.dispatch(request, *args, **kwargs)
  File "D:\python_env\django_env\lib\site-packages\rest_framework\views.py", line 505, in dispatch
    response = self.handle_exception(exc)
  File "D:\python_env\django_env\lib\site-packages\rest_framework\views.py", line 465, in handle_exception
    self.raise_uncaught_exception(exc)
  File "D:\python_env\django_env\lib\site-packages\rest_framework\views.py", line 476, in raise_uncaught_exception
    raise exc
  File "D:\python_env\django_env\lib\site-packages\rest_framework\views.py", line 502, in dispatch
    response = handler(request, *args, **kwargs)
  File "D:\python_env\django_env\lib\site-packages\rest_framework\mixins.py", line 38, in list
    queryset = self.filter_queryset(self.get_queryset())
  File "D:\python_env\django_env\lib\site-packages\rest_framework\generics.py", line 150, in filter_queryset
    queryset = backend().filter_queryset(self.request, queryset, self)
  File "D:\python_env\django_env\lib\site-packages\django_filters\rest_framework\backends.py", line 96, in filter_queryset
    return filterset.qs
  File "D:\python_env\django_env\lib\site-packages\django_filters\filterset.py", line 237, in qs
    qs = self.filter_queryset(qs)
  File "D:\python_env\django_env\lib\site-packages\django_filters\filterset.py", line 227, in filter_queryset
    % (type(self).__name__, name, type(queryset).__name__)
AssertionError: Expected 'GoodsFilter.top_category' to return a QuerySet, but got a NoneType instead.
[2019-10-08 15:23:27,283][Thread-6:18508][task_id:django.request][log.py:228][ERROR][Internal Server Error: /login/]
Traceback (most recent call last):
  File "D:\python_env\django_env\lib\site-packages\django\core\handlers\exception.py", line 34, in inner
    response = get_response(request)
  File "D:\python_env\django_env\lib\site-packages\django\core\handlers\base.py", line 115, in _get_response
    response = self.process_exception_by_middleware(e, request)
  File "D:\python_env\django_env\lib\site-packages\django\core\handlers\base.py", line 113, in _get_response
    response = wrapped_callback(request, *callback_args, **callback_kwargs)
  File "D:\python_env\django_env\lib\site-packages\django\views\decorators\csrf.py", line 54, in wrapped_view
    return view_func(*args, **kwargs)
  File "D:\python_env\django_env\lib\site-packages\django\views\generic\base.py", line 71, in view
    return self.dispatch(request, *args, **kwargs)
  File "D:\python_env\django_env\lib\site-packages\rest_framework\views.py", line 505, in dispatch
    response = self.handle_exception(exc)
  File "D:\python_env\django_env\lib\site-packages\rest_framework\views.py", line 465, in handle_exception
    self.raise_uncaught_exception(exc)
  File "D:\python_env\django_env\lib\site-packages\rest_framework\views.py", line 476, in raise_uncaught_exception
    raise exc
  File "D:\python_env\django_env\lib\site-packages\rest_framework\views.py", line 502, in dispatch
    response = handler(request, *args, **kwargs)
  File "D:\python_env\django_env\lib\site-packages\rest_framework_jwt\views.py", line 57, in post
    if serializer.is_valid():
  File "D:\python_env\django_env\lib\site-packages\rest_framework\serializers.py", line 235, in is_valid
    self._validated_data = self.run_validation(self.initial_data)
  File "D:\python_env\django_env\lib\site-packages\rest_framework\serializers.py", line 433, in run_validation
    value = self.validate(value)
  File "D:\python_env\django_env\lib\site-packages\rest_framework_jwt\serializers.py", line 50, in validate
    user = authenticate(**credentials)
  File "D:\python_env\django_env\lib\site-packages\django\contrib\auth\__init__.py", line 66, in authenticate
    for backend, backend_path in _get_backends(return_tuples=True):
  File "D:\python_env\django_env\lib\site-packages\django\contrib\auth\__init__.py", line 27, in _get_backends
    backend = load_backend(backend_path)
  File "D:\python_env\django_env\lib\site-packages\django\contrib\auth\__init__.py", line 21, in load_backend
    return import_string(path)()
  File "D:\python_env\django_env\lib\site-packages\django\utils\module_loading.py", line 17, in import_string
    module = import_module(module_path)
  File "D:\python_env\django_env\lib\importlib\__init__.py", line 126, in import_module
    return _bootstrap._gcd_import(name[level:], package, level)
  File "<frozen importlib._bootstrap>", line 994, in _gcd_import
  File "<frozen importlib._bootstrap>", line 971, in _find_and_load
  File "<frozen importlib._bootstrap>", line 941, in _find_and_load_unlocked
  File "<frozen importlib._bootstrap>", line 219, in _call_with_frames_removed
  File "<frozen importlib._bootstrap>", line 994, in _gcd_import
  File "<frozen importlib._bootstrap>", line 971, in _find_and_load
  File "<frozen importlib._bootstrap>", line 953, in _find_and_load_unlocked
ModuleNotFoundError: No module named 'users'
[2019-10-12 15:53:29,383][Thread-7:24996][task_id:django.request][log.py:228][ERROR][Internal Server Error: /users/]
Traceback (most recent call last):
  File "D:\python_env\django_env\lib\site-packages\rest_framework_jwt\compat.py", line 33, in get_username
    username = user.get_username()
AttributeError: 'NoneType' object has no attribute 'get_username'

During handling of the above exception, another exception occurred:

Traceback (most recent call last):
  File "D:\python_env\django_env\lib\site-packages\django\core\handlers\exception.py", line 34, in inner
    response = get_response(request)
  File "D:\python_env\django_env\lib\site-packages\django\core\handlers\base.py", line 115, in _get_response
    response = self.process_exception_by_middleware(e, request)
  File "D:\python_env\django_env\lib\site-packages\django\core\handlers\base.py", line 113, in _get_response
    response = wrapped_callback(request, *callback_args, **callback_kwargs)
  File "D:\python_env\django_env\lib\site-packages\django\views\decorators\csrf.py", line 54, in wrapped_view
    return view_func(*args, **kwargs)
  File "D:\python_env\django_env\lib\site-packages\rest_framework\viewsets.py", line 114, in view
    return self.dispatch(request, *args, **kwargs)
  File "D:\python_env\django_env\lib\site-packages\rest_framework\views.py", line 505, in dispatch
    response = self.handle_exception(exc)
  File "D:\python_env\django_env\lib\site-packages\rest_framework\views.py", line 465, in handle_exception
    self.raise_uncaught_exception(exc)
  File "D:\python_env\django_env\lib\site-packages\rest_framework\views.py", line 476, in raise_uncaught_exception
    raise exc
  File "D:\python_env\django_env\lib\site-packages\rest_framework\views.py", line 502, in dispatch
    response = handler(request, *args, **kwargs)
  File "D:\vue_django\backend\apps\user\views.py", line 92, in create
    payload = jwt_payload_handler(user)
  File "D:\python_env\django_env\lib\site-packages\rest_framework_jwt\utils.py", line 34, in jwt_payload_handler
    username = get_username(user)
  File "D:\python_env\django_env\lib\site-packages\rest_framework_jwt\compat.py", line 35, in get_username
    username = user.username
AttributeError: 'NoneType' object has no attribute 'username'
[2019-10-14 10:21:37,382][Thread-16:15168][task_id:django.request][log.py:228][ERROR][Internal Server Error: /goods/]
Traceback (most recent call last):
  File "D:\python_env\django_env\lib\site-packages\django\core\handlers\exception.py", line 34, in inner
    response = get_response(request)
  File "D:\python_env\django_env\lib\site-packages\django\core\handlers\base.py", line 115, in _get_response
    response = self.process_exception_by_middleware(e, request)
  File "D:\python_env\django_env\lib\site-packages\django\core\handlers\base.py", line 113, in _get_response
    response = wrapped_callback(request, *callback_args, **callback_kwargs)
  File "D:\python_env\django_env\lib\site-packages\django\views\decorators\csrf.py", line 54, in wrapped_view
    return view_func(*args, **kwargs)
  File "D:\python_env\django_env\lib\site-packages\rest_framework\viewsets.py", line 114, in view
    return self.dispatch(request, *args, **kwargs)
  File "D:\python_env\django_env\lib\site-packages\rest_framework\views.py", line 505, in dispatch
    response = self.handle_exception(exc)
  File "D:\python_env\django_env\lib\site-packages\rest_framework\views.py", line 465, in handle_exception
    self.raise_uncaught_exception(exc)
  File "D:\python_env\django_env\lib\site-packages\rest_framework\views.py", line 476, in raise_uncaught_exception
    raise exc
  File "D:\python_env\django_env\lib\site-packages\rest_framework\views.py", line 502, in dispatch
    response = handler(request, *args, **kwargs)
  File "D:\python_env\django_env\lib\site-packages\rest_framework\mixins.py", line 43, in list
    return self.get_paginated_response(serializer.data)
  File "D:\python_env\django_env\lib\site-packages\rest_framework\serializers.py", line 757, in data
    ret = super().data
  File "D:\python_env\django_env\lib\site-packages\rest_framework\serializers.py", line 261, in data
    self._data = self.to_representation(self.instance)
  File "D:\python_env\django_env\lib\site-packages\rest_framework\serializers.py", line 675, in to_representation
    self.child.to_representation(item) for item in iterable
  File "D:\python_env\django_env\lib\site-packages\rest_framework\serializers.py", line 675, in <listcomp>
    self.child.to_representation(item) for item in iterable
  File "D:\python_env\django_env\lib\site-packages\rest_framework\serializers.py", line 526, in to_representation
    ret[field.field_name] = field.to_representation(attribute)
  File "D:\python_env\django_env\lib\site-packages\rest_framework\serializers.py", line 675, in to_representation
    self.child.to_representation(item) for item in iterable
  File "D:\python_env\django_env\lib\site-packages\rest_framework\serializers.py", line 675, in <listcomp>
    self.child.to_representation(item) for item in iterable
  File "D:\python_env\django_env\lib\site-packages\rest_framework\serializers.py", line 511, in to_representation
    for field in fields:
  File "D:\python_env\django_env\lib\site-packages\rest_framework\serializers.py", line 372, in _readable_fields
    for field in self.fields.values():
  File "D:\python_env\django_env\lib\site-packages\django\utils\functional.py", line 80, in __get__
    res = instance.__dict__[self.name] = self.func(instance)
  File "D:\python_env\django_env\lib\site-packages\rest_framework\serializers.py", line 360, in fields
    for key, value in self.get_fields().items():
  File "D:\python_env\django_env\lib\site-packages\rest_framework\serializers.py", line 1022, in get_fields
    field_names = self.get_field_names(declared_fields, info)
  File "D:\python_env\django_env\lib\site-packages\rest_framework\serializers.py", line 1078, in get_field_names
    'Got %s.' % type(fields).__name__
TypeError: The `fields` option must be a list or tuple or "__all__". Got str.
[2019-10-14 10:22:43,954][Thread-9:2212][task_id:django.request][log.py:228][ERROR][Internal Server Error: /goods/]
Traceback (most recent call last):
  File "D:\python_env\django_env\lib\site-packages\django\core\handlers\exception.py", line 34, in inner
    response = get_response(request)
  File "D:\python_env\django_env\lib\site-packages\django\core\handlers\base.py", line 115, in _get_response
    response = self.process_exception_by_middleware(e, request)
  File "D:\python_env\django_env\lib\site-packages\django\core\handlers\base.py", line 113, in _get_response
    response = wrapped_callback(request, *callback_args, **callback_kwargs)
  File "D:\python_env\django_env\lib\site-packages\django\views\decorators\csrf.py", line 54, in wrapped_view
    return view_func(*args, **kwargs)
  File "D:\python_env\django_env\lib\site-packages\rest_framework\viewsets.py", line 114, in view
    return self.dispatch(request, *args, **kwargs)
  File "D:\python_env\django_env\lib\site-packages\rest_framework\views.py", line 505, in dispatch
    response = self.handle_exception(exc)
  File "D:\python_env\django_env\lib\site-packages\rest_framework\views.py", line 465, in handle_exception
    self.raise_uncaught_exception(exc)
  File "D:\python_env\django_env\lib\site-packages\rest_framework\views.py", line 476, in raise_uncaught_exception
    raise exc
  File "D:\python_env\django_env\lib\site-packages\rest_framework\views.py", line 502, in dispatch
    response = handler(request, *args, **kwargs)
  File "D:\python_env\django_env\lib\site-packages\rest_framework\mixins.py", line 43, in list
    return self.get_paginated_response(serializer.data)
  File "D:\python_env\django_env\lib\site-packages\rest_framework\serializers.py", line 757, in data
    ret = super().data
  File "D:\python_env\django_env\lib\site-packages\rest_framework\serializers.py", line 261, in data
    self._data = self.to_representation(self.instance)
  File "D:\python_env\django_env\lib\site-packages\rest_framework\serializers.py", line 675, in to_representation
    self.child.to_representation(item) for item in iterable
  File "D:\python_env\django_env\lib\site-packages\rest_framework\serializers.py", line 675, in <listcomp>
    self.child.to_representation(item) for item in iterable
  File "D:\python_env\django_env\lib\site-packages\rest_framework\serializers.py", line 526, in to_representation
    ret[field.field_name] = field.to_representation(attribute)
  File "D:\python_env\django_env\lib\site-packages\rest_framework\serializers.py", line 675, in to_representation
    self.child.to_representation(item) for item in iterable
  File "D:\python_env\django_env\lib\site-packages\rest_framework\serializers.py", line 675, in <listcomp>
    self.child.to_representation(item) for item in iterable
  File "D:\python_env\django_env\lib\site-packages\rest_framework\serializers.py", line 511, in to_representation
    for field in fields:
  File "D:\python_env\django_env\lib\site-packages\rest_framework\serializers.py", line 372, in _readable_fields
    for field in self.fields.values():
  File "D:\python_env\django_env\lib\site-packages\django\utils\functional.py", line 80, in __get__
    res = instance.__dict__[self.name] = self.func(instance)
  File "D:\python_env\django_env\lib\site-packages\rest_framework\serializers.py", line 360, in fields
    for key, value in self.get_fields().items():
  File "D:\python_env\django_env\lib\site-packages\rest_framework\serializers.py", line 1047, in get_fields
    source, info, model, depth
  File "D:\python_env\django_env\lib\site-packages\rest_framework\serializers.py", line 1192, in build_field
    return self.build_unknown_field(field_name, model_class)
  File "D:\python_env\django_env\lib\site-packages\rest_framework\serializers.py", line 1309, in build_unknown_field
    (field_name, model_class.__name__)
django.core.exceptions.ImproperlyConfigured: Field name `images` is not valid for model `GoodsImage`.
[2019-10-15 12:07:16,802][Thread-6:5612][task_id:django.request][log.py:228][ERROR][Internal Server Error: /userfavs/2/]
Traceback (most recent call last):
  File "D:\python_env\django_env\lib\site-packages\django\core\handlers\exception.py", line 34, in inner
    response = get_response(request)
  File "D:\python_env\django_env\lib\site-packages\django\core\handlers\base.py", line 115, in _get_response
    response = self.process_exception_by_middleware(e, request)
  File "D:\python_env\django_env\lib\site-packages\django\core\handlers\base.py", line 113, in _get_response
    response = wrapped_callback(request, *callback_args, **callback_kwargs)
  File "D:\python_env\django_env\lib\site-packages\django\views\decorators\csrf.py", line 54, in wrapped_view
    return view_func(*args, **kwargs)
  File "D:\python_env\django_env\lib\site-packages\rest_framework\viewsets.py", line 114, in view
    return self.dispatch(request, *args, **kwargs)
  File "D:\python_env\django_env\lib\site-packages\rest_framework\views.py", line 505, in dispatch
    response = self.handle_exception(exc)
  File "D:\python_env\django_env\lib\site-packages\rest_framework\views.py", line 465, in handle_exception
    self.raise_uncaught_exception(exc)
  File "D:\python_env\django_env\lib\site-packages\rest_framework\views.py", line 476, in raise_uncaught_exception
    raise exc
  File "D:\python_env\django_env\lib\site-packages\rest_framework\views.py", line 502, in dispatch
    response = handler(request, *args, **kwargs)
  File "D:\python_env\django_env\lib\site-packages\rest_framework\mixins.py", line 90, in destroy
    instance = self.get_object()
  File "D:\python_env\django_env\lib\site-packages\rest_framework\generics.py", line 99, in get_object
    self.check_object_permissions(self.request, obj)
  File "D:\python_env\django_env\lib\site-packages\rest_framework\views.py", line 343, in check_object_permissions
    if not permission.has_object_permission(request, self, obj):
  File "D:\vue_django\backend\apps\utils\permissions.py", line 21, in has_object_permission
    return obj.owner == request.user
AttributeError: 'UserFav' object has no attribute 'owner'
[2019-10-15 15:09:55,050][Thread-37:1388][task_id:django.request][log.py:228][ERROR][Internal Server Error: /docs/]
Traceback (most recent call last):
  File "D:\python_env\django_env\lib\site-packages\django\core\handlers\exception.py", line 34, in inner
    response = get_response(request)
  File "D:\python_env\django_env\lib\site-packages\django\core\handlers\base.py", line 115, in _get_response
    response = self.process_exception_by_middleware(e, request)
  File "D:\python_env\django_env\lib\site-packages\django\core\handlers\base.py", line 113, in _get_response
    response = wrapped_callback(request, *callback_args, **callback_kwargs)
  File "D:\python_env\django_env\lib\site-packages\django\views\decorators\csrf.py", line 54, in wrapped_view
    return view_func(*args, **kwargs)
  File "D:\python_env\django_env\lib\site-packages\django\views\generic\base.py", line 71, in view
    return self.dispatch(request, *args, **kwargs)
  File "D:\python_env\django_env\lib\site-packages\rest_framework\views.py", line 505, in dispatch
    response = self.handle_exception(exc)
  File "D:\python_env\django_env\lib\site-packages\rest_framework\schemas\views.py", line 48, in handle_exception
    return super().handle_exception(exc)
  File "D:\python_env\django_env\lib\site-packages\rest_framework\views.py", line 465, in handle_exception
    self.raise_uncaught_exception(exc)
  File "D:\python_env\django_env\lib\site-packages\rest_framework\views.py", line 476, in raise_uncaught_exception
    raise exc
  File "D:\python_env\django_env\lib\site-packages\rest_framework\views.py", line 502, in dispatch
    response = handler(request, *args, **kwargs)
  File "D:\python_env\django_env\lib\site-packages\rest_framework\schemas\views.py", line 37, in get
    schema = self.schema_generator.get_schema(request, self.public)
  File "D:\python_env\django_env\lib\site-packages\rest_framework\schemas\coreapi.py", line 164, in get_schema
    links = self.get_links(None if public else request)
  File "D:\python_env\django_env\lib\site-packages\rest_framework\schemas\coreapi.py", line 151, in get_links
    link = view.schema.get_link(path, method, base_url=self.url)
AttributeError: 'AutoSchema' object has no attribute 'get_link'
